Workbook

Sheet Pemetaan Kontrak 
C3: M: Mandatory
C4: O: Optional
C5: P: Pilihan
C6: X: Tidak Ada
C7: Status | D7: Kontrak Lumsum | H7: Kontrak Harga Satuan | K7: Kontrak Gabungan | N7: Kontrak Terima Jadi | Q7: Kontrak Kesepakatan Harga Satuan | T7: Kontrak Payung | U7: Kontrak Waktu Penugasan | V7: Kontrak Biaya Plus Imbalan
D8: Barang | E8: Jasa Lainnya | F8: Jasa Konsultansi | G8: Pekerjaan Konstruksi | H8: Barang | I8: Jasa Lainnya | J8: Pekerjaan Konstruksi | K8: Barang | L8: Jasa Lainnya | M8: Pekerjaan Konstruksi | N8: Barang | O8: Jasa Lainnya | P8: Pekerjaan Konstruksi | Q8: Barang | R8: Jasa Lainnya | S8: Pekerjaan Konstruksi | T8: Jasa Konsultansi | U8: Jasa Konsultansi | V8: Barang | W8: Jasa Lainnya | X8: Pekerjaan Konstruksi
B9: Identifier Perjanjian | C9: M | D9: TRUE | E9: TRUE | F9: TRUE | G9: TRUE | H9: TRUE | I9: TRUE | J9: TRUE | K9: TRUE | L9: TRUE | M9: TRUE | N9: TRUE | O9: TRUE | P9: TRUE | Q9: TRUE | R9: TRUE | S9: TRUE | T9: TRUE | U9: TRUE | V9: TRUE | W9: TRUE | X9: TRUE
B10: Dasar Pekerjaan | C10: M | D10: TRUE | E10: TRUE | F10: TRUE | G10: TRUE | H10: TRUE | I10: TRUE | J10: TRUE | K10: TRUE | L10: TRUE | M10: TRUE | N10: TRUE | O10: TRUE | P10: TRUE | Q10: TRUE | R10: TRUE | S10: TRUE | T10: TRUE | U10: TRUE | V10: TRUE | W10: TRUE | X10: TRUE
B11: Definisi | C11: M | D11: TRUE | E11: TRUE | F11: TRUE | G11: TRUE | H11: TRUE | I11: TRUE | J11: TRUE | K11: TRUE | L11: TRUE | M11: TRUE | N11: TRUE | O11: TRUE | P11: TRUE | Q11: TRUE | R11: TRUE | S11: TRUE | T11: TRUE | U11: TRUE | V11: TRUE | W11: TRUE | X11: TRUE
B12: Ruang Lingkup Pekerjaan/Perjanjian | C12: M | D12: TRUE | E12: TRUE | F12: TRUE | G12: TRUE | H12: TRUE | I12: TRUE | J12: TRUE | K12: TRUE | L12: TRUE | M12: TRUE | N12: TRUE | O12: TRUE | P12: TRUE | Q12: TRUE | R12: TRUE | S12: TRUE | T12: TRUE | U12: TRUE | V12: TRUE | W12: TRUE | X12: TRUE
B13: Metodologi dan Tahapan Pelaksanaan Pekerjaan | C13: O | D13: TRUE | E13: TRUE | F13: TRUE | G13: TRUE | H13: TRUE | I13: TRUE | J13: TRUE | K13: TRUE | L13: TRUE | M13: TRUE | N13: TRUE | O13: TRUE | P13: TRUE | Q13: TRUE | R13: TRUE | S13: TRUE | T13: TRUE | U13: TRUE | V13: TRUE | W13: TRUE | X13: TRUE
B14: Nilai Perjanjian | C14: M | D14: TRUE | E14: TRUE | F14: TRUE | G14: TRUE | H14: TRUE | I14: TRUE | J14: TRUE | K14: TRUE | L14: TRUE | M14: TRUE | N14: TRUE | O14: TRUE | P14: TRUE | Q14: TRUE | R14: TRUE | S14: TRUE | T14: TRUE | U14: TRUE | V14: TRUE | W14: TRUE | X14: TRUE
B15: KHS | C15: P | D15: FALSE | E15: FALSE | F15: FALSE | G15: FALSE | H15: FALSE | I15: FALSE | J15: FALSE | K15: FALSE | L15: FALSE | M15: FALSE | N15: FALSE | O15: FALSE | P15: FALSE | Q15: TRUE | R15: TRUE | S15: TRUE | T15: TRUE | U15: FALSE | V15: FALSE | W15: FALSE | X15: FALSE
B16: Harga Satuan | C16: P | D16: FALSE | E16: FALSE | F16: FALSE | G16: FALSE | H16: TRUE | I16: TRUE | J16: TRUE | K16: FALSE | L16: FALSE | M16: FALSE | N16: FALSE | O16: FALSE | P16: FALSE | Q16: FALSE | R16: FALSE | S16: FALSE | T16: FALSE | U16: FALSE | V16: FALSE | W16: FALSE | X16: FALSE
B17: Non Harga Satuan | C17: P | D17: TRUE | E17: TRUE | F17: TRUE | G17: TRUE | H17: FALSE | I17: FALSE | J17: FALSE | K17: TRUE | L17: TRUE | M17: TRUE | N17: TRUE | O17: TRUE | P17: TRUE | Q17: FALSE | R17: FALSE | S17: FALSE | T17: FALSE | U17: TRUE | V17: FALSE | W17: FALSE | X17: FALSE
B18: Cost + Fee | C18: P | D18: FALSE | E18: FALSE | F18: FALSE | G18: FALSE | H18: FALSE | I18: FALSE | J18: FALSE | K18: FALSE | L18: FALSE | M18: FALSE | N18: FALSE | O18: FALSE | P18: FALSE | Q18: FALSE | R18: FALSE | S18: FALSE | T18: FALSE | U18: FALSE | V18: TRUE | W18: TRUE | X18: TRUE
B19: Struktur Organisasi Pelaksanaan | C19: M | D19: TRUE | E19: TRUE | F19: TRUE | G19: TRUE | H19: TRUE | I19: TRUE | J19: TRUE | K19: TRUE | L19: TRUE | M19: TRUE | N19: TRUE | O19: TRUE | P19: TRUE | Q19: TRUE | R19: TRUE | S19: TRUE | T19: TRUE | U19: TRUE | V19: TRUE | W19: TRUE | X19: TRUE
B20: Jangka Waktu | C20: M | D20: TRUE | E20: TRUE | F20: TRUE | G20: TRUE | H20: TRUE | I20: TRUE | J20: TRUE | K20: TRUE | L20: TRUE | M20: TRUE | N20: TRUE | O20: TRUE | P20: TRUE | Q20: TRUE | R20: TRUE | S20: TRUE | T20: TRUE | U20: TRUE | V20: TRUE | W20: TRUE | X20: TRUE
... B65: Penutup | C65: M | D65: TRUE | E65: TRUE | F65: TRUE | G65: TRUE | H65: TRUE | I65: TRUE | J65: TRUE | K65: TRUE | L65: TRUE | M65: TRUE | N65: TRUE | O65: TRUE | P65: TRUE | Q65: TRUE | R65: TRUE | S65: TRUE | T65: TRUE | U65: TRUE | V65: TRUE | W65: TRUE | X65: TRUE

Sheet Master Klausul
B1: Klausul | C1: Data
A2: Header | B2: Perjanjian/Kontrak [Nomor Perjanjian/Kontrak] tentang [Nama Pekerjaan] Antara PT PLN (Persero) dengan [Nama Penyedia Barang/Jasa] | C2: Nomor Perjanjian/Kontrak
C3: Nama Pekerjaan
C4: Nama Penyedia Barang/Jasa
A5: ='Pemetaan Kontrak '!B9 -> Identifier Perjanjian | B5: Perjanjian [Nama Pekerjaan] berikut semua lampirannya dibuat dan disepakati di [Tempat Perjanjian/Kontrak] pada hari [Hari Penandatanganan] tanggal [Tanggal Penandatanganan] oleh dan antara: I. PT PLN (Persero) : Suatu Perseroan Terbatas yang didirikan berdasarkan hukum Republik Indonesia berdasarkan Akta Nomor 169 tanggal 30 Juli 1994, dibuat oleh dan dihadapan Sutjipto, S.H. Notaris di Jakarta, yang telah diubah beberapa kali, terakhir dilakukan perubahan sebagaimana Akta No. [No Akta Perubahan Terakhir] tanggal [tanggal Akta] dibuat oleh dan dihadapan [Notaris]. Notaris di Jakarta, yang dalam hal ini di wakili oleh [Nama pejabat yang menandatangani] selaku [Jabatan Penandatangan] PT PLN (Persero) [Nama Unit] berdasarkan Keputusan Direksi PT PLN (Persero) Nomor: [Nomor SK] tentang [Judul SK], sehingga dalam hal ini berhak dan berwenang bertindak untuk dan atas nama PT PLN (Persero)[Nama Unit], berkedudukan di [Alamat Unit], untuk selanjutnya disebut sebagai PIHAK PERTAMA II. [Nama Penyedia Barang/Jasa] : Suatu [Bentuk Badan Usaha] yang didirikan berdasarkan Hukum Republik Indonesia berdasarkan Akta No. [Nomor Akta Pendirian Perusahaan] tanggal [Tanggal Akta Pendirian] dibuat oleh dan dihadapan [Nama Notaris Pembuat Akta], Notaris di [Kota Notaris], yang telah diubah beberapa kali, terakhir dilakukan perubahan sebagaimana Akta Nomor [Nomor Akta Perubahan Terakhir] tanggal [Tanggal Perubahan Terakhir] dibuat oleh dan dihadapan [Nama Notaris Pembuat Akta], Notaris di [Kota Notaris] yang dalam hal ini diwakili oleh [Nama perwakilan perusahaan] selaku [Jabatan perwakilan] sehingga dalam hal ini berhak dan bewenang bertindak untuk dan atas nama [Nama Penyedia Barang/Jasa], berkedudukan di [Alamat/Kota Domisili Penyedia Barang/Jasa], untuk selanjutnya disebut sebagai PIHAK KEDUA Untuk selanjutnya PIHAK PERTAMA dan PIHAK KEDUA secara sendiri-sendiri disebut PIHAK dan secara Bersama-sama disebut PARA PIHAK. | C5: Nama Pekerjaan
C6: Tempat Perjanjian/Kontrak
C7: Hari penandatanganan
C8: Tanggal Penandatanganan
C9: No Akta Perubahan Terakhir
C10: tanggal Akta
C11: Notaris
C12: Nama pejabat yang menandatangani
C13: Jabatan Penandatangan
C14: Nama Unit
C15: Nomor SK
C16: Judul SK
C17: Alamat Unit
... C27: Alamat/kota domisili Penyedia Barang/Jasa
A28: ='Pemetaan Kontrak '!B10 -> Dasar Pekerjaan | B28: 1. PIHAK PERTAMA dalam menjalankan kegiatan operasionalnya, melakukan [jenis pengadaan] dengan mengacu pada: a. [list] Peraturan 2. PIHAK KEDUA telah menyetujui untuk melaksanakan pekerjaan [Jenis Pengadaan] sesuai dengan persyaratan dan ketentuan dalam Perjanjian/Kontrak ini sesuai dengan dokumen-dokumen sebagaimana berikut: a. Dokumen Tender/RKS No. [Nomor dokumen tender/RKS], tanggal [Tanggal dokumen tender/RKS] beserta addendumnya [apabila ada]. b. Surat Penawaran Sampul 1 (Administrasi dan Teknis) No. [Nomor surat administrasi & teknis] tanggal [Tanggal surat penawaran sampul 1] c. Surat Penawaran Sampul 2 (Harga) No. [Nomor surat penawaran harga] tanggal [Tanggal surat penawaran sampul 2] d. Surat Penunjukan Penyedia Barang/Jasa No. [Nomor SPPBJ/SPPBJ] tanggal [Tanggal surat penunjukan] e. Surat Perintah Mulai Kerja No. [Nomor Surat Perintah Mulai Kerja] tanggal [Tanggal Surat Perintah Mulai Kerja] f. Kesepakatan Diskusi Perjanjian/Kontrak (Contract Discussion Agreement) tanggal [Tanggal Contract Discussion Agreement] g. [Dokumen pendukung tambahan (jika dibutuhkan)] Berdasarkan hal-hal tersebut, maka PARA PIHAK dengan ini sepakat untuk mengikatkan diri dalam sebuah Perjanjian/Kontrak yang berisi syarat-syarat dan ketentuan-ketentuan sebagai berikut: | C28: [list] Peraturan
C29: Jenis Pengadaan
C30: Nomor Dokumen Tender/RKS
C31: Tanggal Dokumen Tender/RKS
C32: Nomor surat administrasi & teknis
C33: Tanggal surat penawaran sampul 1
C34: Nomor surat penawaran harga
C35: Tanggal surat penawaran sampul 2
C36: Nomor SPPBJ/SPPBJ
C37: Tanggal surat penunjukan
C38: Nomor Surat Perintah Mulai Kerja
C39: Tanggal Surat Perintah Mulai Kerja
C40: Tanggal Contract Discussion Agreement
C41: Dokumen pendukung tambahan (jika dibutuhkan)
A42: ='Pemetaan Kontrak '!B11 -> Definisi | B42: 1. Berita Acara Serah Terima Pekerjaan (BASTP) adalah berita acara yang dibuat setelah progres fisik pekerjaan mencapai 100% (seratus persen). 2. Berita Acara Penyerahan Akhir (BAP-Akhir) adalah berita acara yang dibuat untuk menyatakan Hak dan Kewajiban para pihak telah selesai seluruhnya sehingga Perjanjian dinyatakan ditutup. 3. Direksi Pekerjaan adalah Pejabat yang diberi wewenang untuk mengawasi pelaksanaan pekerjaan berdasarkan Perjanjian/Kontrak. [mengikuti definisi tercantum dalam Perdir Nomor 0018.P/DIR/2023 dan sesuai jenis Pengadaan] | C42: Mengikuti definisi tercantum dalam Perdir Nomor 0018.P/DIR/2023 dan sesuai jenis Pengadaan
A43: ='Pemetaan Kontrak '!B12 -> Ruang Lingkup Pekerjaan/Perjanjian | B43: 1. PIHAK PERTAMA memberikan pekerjaan kepada PIHAK KEDUA untuk melaksanakan [Jenis Pengadaan] [Nama Pekerjaan] dan PIHAK KEDUA menerima penugasan tersebut. 2. Uraian [Jenis Pengadaan] tersebut di atas tercantum sebagaimana Lampiran 1 ini dan/atau sesuai dengan Dokumen Pengadaan yang telah ditentukan PIHAK PERTAMA. | C43: Jenis Pengadaan
C44: Nama Pekerjaan
A45: ='Pemetaan Kontrak '!B13 -> Metodologi dan Tahapan Pelaksanaan Pekerjaan | B45: 1. | C45: Freetext
A46: ='Pemetaan Kontrak '!B14 -> Nilai Perjanjian
A47: KHS | B47: 1. Sumber dana yang digunakan dalam pelaksanaan Pekerjaan Perjanjian/Kontrak adalah [APLN/Pinjaman/Hibah Luar Negeri/Pinjaman/Hibah Dalam Negeri]. 2. Harga Satuan adalah sebagaimana ditetapkan pada Perjanjian/Kontrak ini berlaku dan mengikat Para Pihak untuk jangka waktu 1 (satu) tahun atau sepanjang Jangka Waktu Penerbitan. 3. Jenis Perjanjian/Kontrak untuk pekerjaan ini adalah [Jenis Perjanjian/Kontrak]. | C47: Sumber Dana [APLN/Pinjaman/Hibah Luar Negeri/Pinjaman/Hibah Dalam Negeri]
C48: Jenis Perjanjian/Kontrak
A49: Harga Satuan | B49: 1. Sumber dana yang digunakan dalam pelaksanaan Pekerjaan Perjanjian/Kontrak adalah [APLN/Pinjaman/Hibah Luar Negeri/Pinjaman/Hibah Dalam Negeri]. 2. Harga Satuan adalah sebagaimana ditetapkan pada Perjanjian/Kontrak ini berlaku dan mengikat Para Pihak untuk jangka waktu 1 (satu) tahun atau sepanjang Jangka Waktu Penerbitan. 3. PIHAK KEDUA akan melaksanakan Pekerjaan sesuai dengan spesifikasi pada ayat (1) Pasal ini dengan mempertimbangkan volume dan satuan lainnya bersifat indikatif sesuai dengan Lampiran 1 Perjanjian ini. 4. Jenis Perjanjian/Kontrak untuk pekerjaan ini adalah [Jenis Perjanjian/Kontrak]. | C49: Sumber Dana [APLN/Pinjaman/Hibah Luar Negeri/Pinjaman/Hibah Dalam Negeri]
...

Sheet KHS Material Ketenagalistrikan
A1: Pasal | C1: Klausul | D1: Data
B2: Header | C2: PT PLN (PERSERO) KONTRAK KESEPAKATAN HARGA SATUAN PENGADAAN [Nama Pengadaan] No: [Nomor Kontrak] Tanggal: [Tanggal Kontrak] PT PLN (PERSERO) DENGAN PT [Nama Penyedia] | D2: Nama pengadaan
D3: Nomor kontrak
D4: Tanggal kontrak
D5: Nama penyedia
B6: KONTRAK | C6: KONTRAK KESEPAKATAN HARGA SATUAN PENGADAAN [MASUKAN NAMA PENGADAAN] Kontrak Kesepakatan Harga Satuan Pengadaan [Nama Pengadaan] berikut semua lampirannya (selanjutnya disebut Kontrak) dibuat dan disepakati di Jakarta pada hari [Hari] tanggal [Tanggal] oleh dan antara: I. PT PLN (PERSERO), suatu perusahaan perseroan yang didirikan berdasarkan hukum Negara Republik Indonesia, berdasarkan Akta Notaris Sutjipto, SH, di Jakarta Nomor 169 tanggal 30 Juli 1994, sebagaimana telah diubah dan terakhir berdasarkan akta Notaris [Notaris] Nomor [No Akta Perubahan Terakhir] tanggal [tanggal akta], dalam hal ini diwakili secara sah oleh [Nama Pengguna] selaku [Jabatan] berdasarkan Keputusan Menteri Badan Usaha Milik Negara selaku RUPS PT PLN (Persero) No. [Nomor SK] tanggal [Tanggal SK] tentang [perihal SK], berkedudukan di [Alamat Unit], selanjutnya disebut Pihak Pertama; dan II. PT [Nama Penyedia], suatu perseroan terbatas yang didirikan berdasarkan hukum Negara Republik Indonesia, berdasarkan Akta Notaris [Nama Notaris] di [Tempat Kewenangan Notaris] Nomor [Nomor Akta] tanggal [Tanggal] sebagaimana telah diubah dan terakhir dengan Akta Notaris [Nama Notaris] di [Tempat Kewenangan Notaris] Nomor [Nomor Akta] tanggal [Masukan Tanggal], dalam hal ini diwakili secara sah oleh [Nama] selaku [Jabatan] berdasarkan [Dasar Kewenangan], berkedudukan di [Domisili], selanjutnya disebut Pihak Kedua. (Selanjutnya Pihak Pertama dan Pihak Kedua secara sendiri-sendiri disebut Pihak dan secara bersama-sama disebut Para Pihak). Para Pihak terlebih dahulu menerangkan hal-hal sebagai berikut: A. Pihak Pertama telah melakukan [Metode Pengadaan] untuk pengadaan [Nama Pengadaan] sesuai Dokumen RKS Nomor [Nomor RKS] tanggal [Masukan Tanggal] secara tepat dan cepat untuk memenuhi kebutuhan operasional Pihak Pertama di seluruh Indonesia. B. Pihak Pertama telah menunjuk Pihak Kedua sebagai salah satu pemenang untuk pengadaan [Nama Pengadaan] tahun [Tahun Pengadaan] melalui surat penunjukan pemenang Nomor [Nomor SPPBJ] tanggal [Tanggal] sebagaimana dilampirkan dalam Lampiran 4 Kontrak ini. C. Pihak Kedua telah memiliki sertifikat Sistem Pengawasan Mutu (SPM) yang berlaku di lingkungan Pihak Pertama / Surat Rekomendasi Mutu (SRM) yang berlaku di lingkungan Pihak Pertama / TPG / Spesifikasi Teknis [disesuaikan terhadap kebutuhan masing-masing pengadaan] sebagaimana terlampir dalam Lampiran 5 Kontrak ini. D. Pihak Kedua telah menandatangani Pakta Integritas sebagaimana terlampir dalam Lampiran 6 Kontrak ini. E. Pihak Kedua menyatakan kepada Pihak Pertama, bahwa Pihak Kedua memiliki keahlian profesional, personil, dan sumber daya teknis, serta telah menyetujui untuk melaksanakan Pekerjaan sesuai dengan persyaratan dan ketentuan dalam Kontrak ini. Berdasarkan hal-hal tersebut di atas, Para Pihak dengan ini sepakat untuk membuat, menandatangani dan melaksanakan Kontrak dengan syarat dan ketentuan sebagai berikut: | D6: Nama pengadaan
D7: Hari
D8: Tanggal
D9: Notaris
D10: No Akta Perubahan Terakhir
D11: tanggal Akta
D12: Nama Pengguna
D13: Jabatan
D14: Nomor SK
D15: Tanggal SK
D16: perihal SK
D17: Alamat Unit
D18: Nama Penyedia
... D32: Jenis Sertifikasi/Spesifikasi Teknis
A33: Pasal 1 | B33: DEFINISI DAN INTERPRETASI | C33: (1) Definisi adalah uraian atau pengertian mengenai istilah-istilah yang digunakan dalam Kontrak. Istilah-istilah tersebut dijelaskan dan diberi arti atau tafsiran sehingga isi Kontrak mudah dipahami oleh setiap orang yang membacanya dan tidak ditafsirkan atau diartikan lain. Dalam Kontrak ini yang dimaksud dengan: (a) Amendemen adalah seluruh perubahan atau penambahan yang diperlukan terhadap Kontrak. (b) Barang adalah suatu material beserta peralatan dan perlengkapannya yang spesifikasinya ditetapkan oleh Pihak Pertama yang mengacu pada Dokumen RKS beserta perubahannya sebagaimana dirinci dalam Lampiran 2 Kontrak ini. (c) Barang Rusak adalah Barang yang cacat produksi atau terdapat ketidaksesuaian baik secara fisik maupun fungsi atau tidak sesuai spesifikasi dan/atau tidak berfungsi sebagian maupun secara keseluruhan (untuk perangkat keras maupun perangkat lunak) baik terpasang maupun belum terpasang sebagaimana disyaratkan dalam Kontrak, sebelum maupun setelah diterima oleh Pengguna Kontrak Rinci, yang disebabkan oleh kesalahan Pihak Kedua. (d) BASTB adalah Berita Acara Serah Terima Barang sebagaimana dirinci lebih lanjut dalam Pasal 15 Kontrak ini dengan format sebagaimana terlampir dalam Lampiran 13 Kontrak ini. (e) Cacat Mutu adalah keadaan hasil Pekerjaan Penyediaan Barang yang tidak berfungsi sesuai dengan persyaratan dalam Kontrak ini. (f) Daftar Penyedia Terseleksi (DPT) adalah daftar Penyedia Barang/Jasa yang dinyatakan lulus oleh Pihak Pertama melalui mekanisme penilaian kualifikasi. (g) Direksi Pekerjaan adalah Senior Manager Perencanaan selaku wakil dari Pengguna Kontrak Rinci pada Unit Induk yang memiliki fungsi pengendalian dan pengawasan Kontrak Rinci serta berwenang untuk menandatangani berita acara sehubungan dengan pelaksanaan Pekerjaan serta melaporkannya secara periodik kepada Wakil Pihak Pertama sebelum dilakukannya Serah Terima Barang. (h) Dokumen Tender atau Rencana Kerja dan Syarat-syarat (Dokumen RKS) adalah dokumen yang disiapkan oleh Pihak Pertama sebagai pedoman dalam proses pembuatan dan penyampaian penawaran oleh Pihak Kedua serta pedoman evaluasi penawaran oleh Pihak Pertama. (i) Estimasi Volume adalah proyeksi volume Barang yang dibutuhkan dalam Tahun Kontrak yang dapat berubah berdasarkan Evaluasi Kinerja sebagaimana dirinci dalam Lampiran 2 Kontrak ini. (j) Evaluasi Kinerja adalah penilaian yang dilakukan oleh Pihak Pertama atas kinerja Pihak Kedua dalam pelaksanaan pekerjaan kontraktual berdasarkan metriks penilaian kinerja kontraktual Penyedia Barang/Jasa yang berlaku di Lingkungan PT PLN (Persero). (k) Harga Satuan adalah harga satuan atas masing-masing Pekerjaan Penyediaan Barang dan Pekerjaan Transportasi sebagaimana dimaksud dalam Pasal 5 Kontrak ini. (l) Jaminan Pelaksanaan adalah jaminan dalam bentuk bank garansi yang diterbitkan oleh pihak-pihak yang dapat menerbitkan jaminan di lingkungan Pihak Pertama yang akan disediakan oleh Pihak Kedua untuk kepentingan Pengguna Kontrak Rinci, dengan tujuan menjamin kewajiban-kewajiban Pihak Kedua berdasarkan Kontrak Rinci. (m) Jangka Waktu Kontrak Rinci adalah jangka waktu berlakunya Kontrak Rinci sebagaimana ditetapkan dalam Kontrak Rinci. (n) Kerugian Langsung adalah kerugian yang diderita oleh Pihak Pertama dan/atau Pengguna Kontrak Rinci karena Barang Rusak atau Cacat Mutu yang mengakibatkan timbulnya peristiwa-peristiwa tertentu yang berdampak langsung kepada Pihak Pertama dan/atau Pengguna Kontrak Rinci, termasuk namun tidak terbatas pada kerusakan atas suatu peralatan, perlengkapan, atau fasilitas Pihak Pertama dan/atau Pengguna Kontrak Rinci. (o) Kontrak Rinci adalah dokumen yang tidak terpisahkan dan menjadi satu kesatuan dengan Kontrak ini. Kontrak Rinci ditandatangani oleh Pengguna Kontrak Rinci untuk mengatur secara rinci mengenai syarat dan ketentuan pelaksanaan Kontrak ini termasuk namun tidak terbatas pada spesifikasi dan ruang lingkup pekerjaan yang akan dilakukan Pihak Kedua, jumlah Barang yang akan dibeli, nilai pembayaran, serta syarat dan ketentuan lainnya yang terkait dengan pelaksanaan Pekerjaan berdasarkan Kontrak ini. (p) Lokasi adalah tempat penerimaan Barang baik pada lokasi PLN Unit Induk atau PLN Unit Pelaksana atau tempat lain yang ditunjuk oleh PLN sebagai destinasi pengiriman Barang sebagaimana dirinci dalam Lampiran 3 Kontrak ini atau sebagaimana ditetapkan lebih lanjut dalam Kontrak Rinci. (q) Pekerjaan adalah Pekerjaan Penyediaan Barang dan Pekerjaan Transportasi. (r) Pekerjaan Penyediaan Barang adalah setiap dan/atau seluruh penyediaan Barang yang meliputi pabrikasi, pengujian, termasuk telah memenuhi SPLN dan pengepakan yang dapat dilakukan secara bertahap termasuk garansi atas Barang yang akan dilaksanakan oleh Pihak Kedua sebagaimana tercantum dalam Lampiran 1 dan Lampiran 2 Kontrak ini. (s) Pekerjaan Transportasi adalah setiap dan/atau seluruh pengiriman atau pengangkutan, bongkar muat, dan asuransi atas Pekerjaan Penyediaan Barang sampai dengan diterimanya Barang oleh Pihak Pertama di Lokasi yang akan dilaksanakan oleh Pihak Kedua, dengan daftar Lokasi pengiriman, biaya transportasi termasuk asuransi sebagaimana dirinci dalam Lampiran 1 dan Lampiran 3 Kontrak ini. (t) Pengguna Kontrak Rinci adalah: 1) [[list] Pengguna] (u) PLN Sub Holding/Anak Perusahaan PLN adalah perusahaan yang sahamnya lebih dari 50% (lima puluh persen) dimiliki oleh PLN. (v) PLN Unit Induk adalah organisasi 1 (satu) tingkat di bawah Kantor Pusat yang dipimpin, dibina, dan dikelola oleh General Manager dan melaksanakan kegiatan usaha penyediaan tenaga listrik tertentu sesuai dengan tujuannya. (w) PLN Unit Pelaksana adalah organisasi 1 (satu) tingkat di bawah Unit Induk atau Pusat-Pusat yang dipimpin, dibina, dan dikelola oleh Manager Unit Pelaksana dan melaksanakan kegiatan ketenagalistrikan tertentu sesuai dengan tujuannya. (x) SCM Marketplace adalah aplikasi yang digunakan untuk pelaksanaan transaksi pembelian Barang/Jasa secara realtime dan akuntabel yang terintegrasi dengan aplikasi PLN, Uji Serah Terima (UST) PLN Pusertif dan tracking pengiriman Barang/Jasa. (y) Sistem Pengawasan Mutu (SPM) adalah sistem pengawasan yang dilakukan oleh PT PLN (Persero) Pusat Sertifikasi terhadap pabrikan dalam negeri yang memproduksi material ketenagalistrikan yang akan digunakan pada instalasi ketenagalistrikan di lingkungan Pihak Pertama dan anak perusahaan Pihak Pertama untuk menjaga mutu produk material/peralatan sesuai dengan standar, dibuktikan dengan terbitnya sertifikat SPM. (z) Standar Perusahaan Listrik Negara (SPLN) adalah standar perusahaan Pihak Pertama yang ditetapkan Direksi Pihak Pertama, bersifat wajib dan dapat berupa peraturan, pedoman, instruksi, cara pengujian dan spesifikasi yang berlaku di lingkungan Pihak Pertama. (aa) Surat Perintah Mulai Kerja (SPMK) adalah surat yang dikeluarkan oleh Pengguna Kontrak Rinci kepada Pihak Kedua yang menyatakan Tanggal Efektif Kontrak Rinci dan untuk memulai pelaksanaan Pekerjaan dengan format sebagaimana Lampiran 8 Kontrak ini, dengan syarat sebagaimana diatur lebih lanjut dalam Kontrak Rinci. (bb) Surat Rekomendasi Mutu (SRM) adalah bukti penilaian awal bahwa suatu pabrikan luar negeri dan agen tunggalnya mempunyai kemampuan dalam memproduksi dan mengedarkan material impor sesuai dengan standar. (cc) Tahun Kontrak adalah tahun sejak tanggal ditandatanganinya Kontrak sampai dengan tahun berakhirnya masa berlaku Kontrak. (dd) Technical Particular and Guarantee (TPG) adalah spesifikasi teknis dan jaminan berdasarkan Dokumen RKS merujuk pada penawaran Pihak Kedua yang telah dievaluasi serta dapat diterima oleh Pihak Pertama. (ee) Tim Pemeriksa Barang adalah petugas-petugas pada PLN Unit Induk atau PLN Unit Pelaksana yang ditunjuk oleh Pengguna Kontrak Rinci termasuk tim yang dibentuk oleh manager unit untuk melaksanakan tugas-tugas sebagaimana diatur dalam Kontrak ini. (ff) Tingkat Komponen Dalam Negeri (TKDN) adalah besaran kandungan dalam negeri pada Barang, jasa, serta gabungan Barang dan jasa, yang dipersyaratkan berdasarkan peraturan perundang-undangan yang berlaku dari waktu ke waktu. (gg) Wakil Pihak Pertama adalah wakil Pihak Pertama yang ditunjuk untuk melakukan pengendalian terhadap pelaksanaan Kontrak ini, sebagaimana di atur pada Pasal 9 Kontrak ini. | D33: [list] Pengguna
A36: Pasal 2 | B36: Hierarki Dokumen | C36: Dalam hal terjadi perbedaan penafsiran atau pertentangan antara ketentuan dalam satu dokumen dengan dokumen lain, maka yang berlaku adalah ketentuan dalam dokumen yang lebih tinggi berdasarkan urutan hierarki sebagai berikut: (a) Kontrak Kesepakatan Harga Satuan beserta perubahannya. (b) Kontrak Rinci beserta perubahannya. (c) Surat Penunjukkan Penyedia Barang/Jasa (SPPBJ). (d) Contract Discussion Agreement (CDA). (e) Addendum/Amendemen Dokumen RKS (apabila ada). (f) Spesifikasi Teknis. (g) Gambar-Gambar (Apabila ada). (h) Daftar kuantitas dan Harga. (i) Instruksi Kepada Penyedia Barang/Jasa. (j) Dokumen lain yang merupakan bagian dari Dokumen Tender/RKS. (k) Surat Penawaran Penyedia Barang/Jasa. | D36: -
A37: Pasal 3 | B37: INTEGRITAS DAN TATA KELOLA PERUSAHAAN YANG BAIK | C37: (1) Sehubungan dengan Kontrak dan hal-hal, dokumen-dokumen, kegiatan-kegiatan, dan transaksi-transaksi yang dimaksud dalam atau terkait dengan Kontrak, Para Pihak menyepakati tidak akan melakukan tindakan-tindakan yang mengakibatkan terjadinya ketidakwajaran dalam pelaksanaan Kontrak termasuk namun tidak terbatas pada tindakan penipuan, penggelapan, pemerasan, kolusi, penyuapan, gratifikasi, korupsi, kecurangan, pemalsuan dan tindakan lain yang tidak sesuai dengan etika bisnis yang baik serta bertentangan dengan peraturan perundang-undangan yang berlaku, termasuk mengenai pemberantasan tindak pidana korupsi, pencegahan dan pemberantasan tindak pidana pencucian uang, penerapan praktik tata kelola perusahaan yang baik (Good Corporate Governance atau GCG) pada Badan Usaha Milik Negara (BUMN), termasuk peraturan yang mengatur mengenai tata kelola anti penyuapan yang berlaku di lingkungan Pihak Pertama. (2) Para Pihak menyepakati bahwa Kontrak dilaksanakan dengan itikad baik, tidak saling mempengaruhi baik langsung maupun tidak langsung guna memenuhi keinginannya, menerima serta bertanggungjawab atas segala keputusan yang ditetapkan sesuai dengan kesepakatan Para Pihak, menghindari serta mencegah terjadinya benturan kepentingan (conflict of interest), menghindari serta mencegah penyalahgunaan wewenang dan/atau kolusi dengan tujuan untuk keuntungan pribadi, golongan atau pihak lain, dan tidak memberi dan/atau menerima, tidak menawarkan atau tidak menjanjikan untuk memberi atau menerima hadiah, imbalan berupa apa saja kepada siapapun yang diketahui atau patut diduga berkaitan dengan pelaksanaan Kontrak. (3) Pihak Kedua menyatakan, menjamin dan berkomitmen kepada Pihak Pertama bahwa dalam melaksanakan Kontrak akan mematuhi ketentuan hukum yang berlaku, termasuk namun tidak terbatas pada peraturan perundang-undangan terkait anti korupsi, anti pencucian uang serta kebijakan Pihak Pertama mengenai anti-fraud dan tata kelola anti-penyuapan seperti: (a) Menerapkan 4 NO (TIDAK), yaitu: (i) No bribery, menghindari suap menyuap dan pemerasan; (ii) No gift, menghindari hadiah atau gratifikasi yang bertentangan dengan peraturan yang berlaku; (iii) No kickback, menghindari komisi, tanda terima kasih baik dalam bentuk uang atau bentuk lainnya; dan (iv) No luxurious hospitality, menghindari jamuan yang berlebihan. (b) Mengikuti prosedur uji kelayakan berbasis integritas (Integrity Due Diligence) yang diterapkan Pihak Pertama. (c) Mengikuti program sosialisasi Sistem Manajemen Anti-Penyuapan yang dilaksanakan Pihak Pertama yang dapat diwakili oleh karyawan perusahaan Pihak Kedua yang ditunjuk untuk mewakili Pihak Kedua. (d) Menandatangani dan melaksanakan Pakta Integritas Pihak Kedua. (e) Melaporkan insiden fraud melalui Whistle Blowing System Pihak Pertama. (4) Pihak Pertama akan melakukan audit terkait tagihan pembayaran dan dokumen pembukuan serta pencatatan Pihak Kedua ketika terdapat indikasi ketidakwajaran berupa overcharge atau overprice dari tagihan yang disampaikan oleh Pihak Kedua kepada Pihak Pertama, dimana tujuan pelaksanaan audit tersebut untuk memastikan kesesuaian tagihan Pihak Kedua dengan ketentuan yang berlaku termasuk kesesuaian dengan ketentuan dalam Kontrak. (5) Pelaksanaan audit sebagaimana dimaksud dalam ayat (4) Pasal ini, dilakukan dengan ketentuan sebagai berikut: (a) atas biaya Pihak Pertama; (b) dilakukan dengan pemberitahuan oleh Pihak Pertama kepada Pihak Kedua selambat-lambatnya 7 (tujuh) hari kalender sebelum pelaksanaan audit; (c) pelaksanaan audit dilaksanakan paling lambat dalam waktu 7 (tujuh) hari kerja, dilanjutkan dengan pembuatan pelaporan audit oleh Pihak Pertama paling lambat dalam 3 (tiga) hari kerja; (d) penyelesaian pembayaran (settlement/adjustment) dilakukan paling lambat dalam 30 (tiga puluh) hari kalender setelah Pihak Pertama memaparkan laporan hasil audit kepada Pihak Kedua; (e) Pihak Pertama dapat menunjuk pihak lain untuk melakukan audit; (f) Pihak Kedua wajib mengizinkan perwakilan Pihak Pertama dan menyediakan dokumen dan data yang diperlukan; (g) permintaan dan penyampaian dokumen dan data audit dilaksanakan pada jam kerja Pihak Kedua; (h) apabila terdapat kerjasama antara Pihak Kedua dengan pihak ketiga yang berkaitan dengan pelaksanaan Kontrak, maka Pihak Kedua wajib memastikan dan menuangkan ketentuan mengenai hak akses Pihak Pertama terhadap dokumen dan data milik pihak ketiga dalam perjanjian antara Pihak Kedua dengan pihak ketiga tersebut; dan (i) Para Pihak termasuk perwakilannya, akan menjaga kerahasiaan informasi non-publik yang diperoleh dari pelaksanaan audit tersebut. (6) Dalam pelaksanaan audit terhadap tagihan pembayaran sebagaimana dimaksud ayat (4) Pasal ini, Pihak Pertama berhak melakukan penundaan pembayaran atas tagihan pembayaran tersebut atau dapat melakukan pembayaran melalui suatu rekening khusus (escrow account) yang dibuat oleh Para Pihak yang beban biayanya menjadi tanggung jawab Pihak Kedua sampai dilakukan penyesuaian pembayaran. (7) Dalam hal dilakukan audit sebagaimana dimaksud ayat (4) Pasal ini dan/atau pelaksanaan penundaan pembayaran sebagaimana dimaksud ayat (6) Pasal ini, maka Pihak Kedua wajib untuk tetap melaksanakan kewajibannya sesuai Kontrak ini. (8) Dalam rangka penerapan tata kelola yang baik (Good Corporate Governance) di lingkungan Pihak Pertama, apabila dalam proses pelaksanaan Kontrak ini Pihak Kedua mengetahui adanya tindakan kecurangan, pelanggaran peraturan atau hukum, konflik kepentingan, penyuapan atau gratifikasi, maupun kelakuan tidak etis yang dilakukan oleh pegawai Pihak Pertama, maka Pihak Kedua agar melaporkannya melalui Whistle Blower System dengan menggunakan media antara lain yaitu: (a) Website : https://cos.pln.co.id; (b) Telepon atau Pesan Singkat (SMS) atau Whatsapp ke nomor: 08119861901; atau (c) Email ke: wbpln@pln.co.id; atau (d) Surat kepada Executive Vice President Kepatuhan PT PLN (Persero) Kantor Pusat Jalan Trunojoyo Blok M – I No. 135 Kebayoran Baru, Jakarta 12160. (9) Pihak Kedua yang menurut penilaian Pihak Pertama sehubungan dengan pelaksanaan Kontrak terbukti melakukan larangan-larangan sebagaimana dimaksud pada Pasal ini dapat dikenakan sanksi oleh Pihak Pertama, yaitu sebagai berikut: (a) Pemutusan Kontrak secara sepihak; (b) dalam hal terjadi pemutusan Kontrak, maka Jaminan Pelaksanaan akan dicairkan dan disetorkan ke rekening Pihak Pertama; dan (c) Pihak Kedua dikenakan sanksi daftar hitam (blacklist) sesuai ketentuan yang berlaku di Pihak Pertama. | D37: -
A40: Pasal 4 | B40: LINGKUP PEKERJAAN | C40: (1) Pihak Kedua setuju untuk melaksanakan, menyelesaikan dan melengkapi setiap dan seluruh Pekerjaan dalam semua aspek dan sesuai dengan ketentuan-ketentuan dalam Kontrak ini, dengan lingkup pekerjaan sebagai berikut: (a) Pekerjaan Penyediaan Barang; dan (b) Pekerjaan Transportasi. (2) Pekerjaan Penyediaan Barang merujuk pada: (a) Rincian spesifikasi dan Harga Satuan atas Pekerjaan Penyediaan Barang sebagaimana ditetapkan dalam Lampiran 1 Kontrak ini; dan (b) besaran Estimasi Volume atas Barang serta komitmen kesanggupan kapasitas produksi Barang sebagaimana ditetapkan dalam Lampiran 2 Kontrak ini. (3) Pekerjaan Transportasi merujuk pada rincian Lokasi pengiriman dengan biaya transportasi berikut asuransi sebagaimana ditetapkan dalam Lampiran 1 dan Lampiran 3 Kontrak ini. | D40: -
A41: Pasal 5 | B41: HARGA SATUAN | C41: (1) Harga Satuan adalah sebagaimana ditetapkan dalam Lampiran 1 Kontrak ini berlaku dan mengikat Para Pihak untuk jangka waktu 1 (satu) tahun atau sepanjang Jangka Waktu Penerbitan. | D41: -
A42: Pasal 6 | B42: ESTIMASI VOLUME BARANG | C42: (1) Estimasi Volume sebagaimana dirinci pada Lampiran 2 Kontrak ini adalah merupakan acuan awal dan bukan merupakan komitmen pemesanan dan pembelian Barang dan pelaksanaan Pekerjaan. (2) Komitmen pemesanan dan pembelian Barang serta pelaksanaan Pekerjaan Penyediaan Barang dan Pekerjaan Transportasi secara rinci dan aktual yang akan dipasok oleh Pihak Kedua kepada Pihak Pertama adalah merujuk pada besaran volume dan jadwal pengiriman yang ditetapkan dalam masing-masing Kontrak Rinci. (3) Sebagai bagian dari Pekerjaan Penyediaan Barang, Pihak Kedua wajib untuk memastikan dan menyediakan Barang sebesar Estimasi Volume dan sesuai dengan komitmen kesanggupan kapasitas produksi Barang sebagaimana tercantum pada Lampiran 2 Kontrak ini. | D42: -
A43: Pasal 7 | B43: JANGKA WAKTU BERLAKUNYA KONTRAK | C43: (1) Kontrak ini akan berlaku efektif dan mengikat sejak ditandatangani oleh Para Pihak dan akan terus menerus berlaku sampai dengan seluruh hak dan kewajiban yang timbul dari seluruh Kontrak Rinci terpenuhi. (2) Kontrak Rinci dapat diterbitkan setelah Kontrak ini berlaku efektif sampai dengan tanggal [Tanggal] (Jangka Waktu Penerbitan), kecuali Kontrak ini disepakati untuk diakhiri lebih awal sebagaimana dimaksud dalam Pasal 31 Kontrak ini atau terjadi pemutusan Kontrak sebagaimana dimaksud dalam Pasal 31 Kontrak ini. (3) Apabila Jangka Waktu Penerbitan sebagaimana diatur dalam ayat (2) Pasal ini telah terlampaui, maka Pengguna Kontrak Rinci tidak dapat menerbitkan Kontrak Rinci. Jangka Waktu Penerbitan ini dapat diperpanjang oleh Para Pihak berdasarkan kesepakatan bersama sebelum berakhirnya Jangka Waktu Penerbitan dengan tanpa adanya penambahan volume. Perubahan Jangka Waktu Penerbitan ini selanjutnya dituangkan dalam suatu Amendemen. (4) Masa berlaku Kontrak Rinci dapat melampaui Jangka Waktu Penerbitan dan segala kewajiban Para Pihak tetap berlaku sesuai dengan syarat dan ketentuan yang diatur dalam Kontrak ini dan Kontrak Rinci. | D43: Tanggal berakhirnya Kontrak Rinci
A44: Pasal 8 | B44: PENERBITAN KONTRAK RINCI DAN PELAKSANAAN PEKERJAAN | C44: (1) Setelah ditandatanganinya Kontrak ini, Pihak Kedua akan menandatangani suatu Kontrak Rinci dengan masing-masing Pengguna Kontrak Rinci sesuai dengan format dalam Lampiran 7 Kontrak ini yang merupakan satu kesatuan yang tidak terpisahkan dari Kontrak ini. (2) Pembuatan dan penandatanganan Kontrak Rinci termasuk pemberian Pekerjaan dilakukan berdasarkan pada kebutuhan dan ketersediaan anggaran pada masing-masing PLN Unit Induk/PLN Unit Pelaksana terkait dengan tetap merujuk pada komitmen kesanggupan kapasitas produksi Barang dalam Lampiran 2 Kontrak ini. (3) Sejak tanggal efektif Kontrak Rinci yang ditandai dengan terbitnya SPMK (Tanggal Efektif Kontrak Rinci), Pihak Kedua akan melaksanakan dan menyelesaikan tiap-tiap Pekerjaan sesuai dengan jadwal dan jangka waktu sebagaimana dirinci pada Lampiran 3 Kontrak ini atau Kontrak Rinci (Jangka Waktu Pelaksanaan Pekerjaan). (4) Pelaksanaan Pekerjaan pada Kontrak Rinci tetap mengacu pada Jangka Waktu Pelaksanaan Pekerjaan sebagaimana diatur pada Lampiran 3 Kontrak ini yang akan ditentukan lebih lengkap dalam Kontrak Rinci bersangkutan. (5) Konsekuensi dan risiko atas terjadinya keterlambatan pelaksanaan Pekerjaan sebagaimana diatur dalam Kontrak Rinci maka diberlakukan sesuai ketentuan dalam Kontrak ini. | D44: -
A45: Pasal 9 | B45: PENGENDALIAN DAN PENGAWASAN | C45: (1) Pihak Pertama menunjuk [Satuan Kerja Pengendalian Kontrak] sebagai wakil Pihak Pertama untuk melakukan pengendalian terhadap pelaksanaan Kontrak ini. (2) Untuk kelancaran pelaksanaan Pekerjaan, Pengguna Kontrak Rinci yang relevan berwenang untuk membuat Kontrak Rinci dan dibantu oleh Direksi Pekerjaan untuk bertanggung jawab untuk melakukan pengendalian dan pengawasan terhadap pelaksanaan Pekerjaan, serta memberikan bimbingan dan petunjuk yang diperlukan demi kelancaran pelaksanaan Pekerjaan. (3) Pengguna Kontrak Rinci dapat memberikan peringatan tertulis kepada Pihak Kedua dalam hal terdapat ketidaksesuaian pelaksanaan Kontrak Rinci sebagaimana Pasal 27 berdasarkan laporan dan justifikasi dari Manager Unit Pelaksana. (4) Pengguna Kontrak Rinci dalam melaksanakan tugasnya sebagaimana dimaksud pada ayat (2) Pasal ini dapat menunjuk Tim Pemeriksa Barang. (5) Pihak Pertama atau wakil Pihak Pertama memiliki kewenangan untuk melakukan hal-hal sebagai berikut: (a) melaksanakan koordinasi, monitoring dan pengaturan kuota dan/atau alokasi Barang; (b) melakukan pemeriksaan dan verifikasi atas hasil Evaluasi Kinerja Pihak Kedua yang dilakukan oleh masing-masing Pengguna Kontrak Rinci; (c) memberikan peringatan tertulis kepada Pihak Kedua dalam hal Pihak Kedua tidak dapat melaksanakan sebagian atau seluruh kewajibannya sebagaimana disebutkan dalam Kontrak ini; (d) memberikan peringatan tertulis kepada Pihak Kedua berdasarkan hasil Evaluasi Kinerja Pihak Kedua atas pelaksanaan Pekerjaan; (e) mendorong Peningkatan Penggunaan Produksi Dalam Negeri (P3DN) melalui pelaksanaan audit TKDN dengan melakukan verifikasi data antara lain namun tidak terbatas pada bill of material, purchase order komponen material, dokumen impor, dan dokumen lain yang berhubungan dengan produksi Barang. (6) Pihak Pertama memiliki kewenangan untuk menunjuk PT PLN (Persero) Pusat Sertifikasi atau pihak lainnya guna melakukan monitoring proses produksi dan audit kesiapan produksi yang meliputi jadwal produksi, kesiapan sarana dan pengujian, kesiapan SDM, serta kesiapan bahan baku yang akan dilakukan segera setelah Kontrak ditandatangani dengan merujuk pada jadwal yang ditetapkan Pihak Pertama. Monitoring proses produksi dan audit kesiapan produksi dapat dilakukan secara berkala sesuai kebutuhan Pihak Pertama. Setiap hasil monitoring proses produksi dan audit kesiapan produksi akan dilaporkan oleh pihak yang ditunjuk Pihak Pertama. (7) Pihak Pertama memiliki kewenangan untuk melakukan pengawasan, pengujian atau audit Pekerjaan yang sudah dan sedang dilaksanakan oleh Pihak Kedua, termasuk namun tidak terbatas pada penyediaan material kualitas tinggi sesuai spesifikasi yang dipersyaratkan, komponen material yang digunakan berasal dari penyedia komponen yang berkualitas, dan sistem kontrol kualitas internal sesuai dengan SPLN atau standar lainnya yang berlaku. Biaya pengawasan, pengujian atau audit menjadi beban Pihak Pertama. (8) Pihak Kedua wajib menyediakan akses kepada Pihak Pertama dalam melakukan monitoring proses produksi dan audit kesiapan produksi, pengawasan, pengujian, dan/atau audit Pekerjaan. Pihak Kedua wajib memberikan dokumentasi yang dibutuhkan dan klarifikasi selama proses tersebut berlangsung untuk menjamin kualitas Barang sesuai spesifikasi yang dipersyaratkan dalam Kontrak. | D45: Satuan Kerja Pengendalian Kontrak
A47: Pasal 10 | B47: UJI SERAH TERIMA | C47: (1) Pihak Kedua wajib menyediakan Barang yang dibutuhkan oleh Pihak Pertama agar dapat dilakukan uji serah terima. (2) Ketentuan uji serah terima merupakan bagian yang tidak terpisahkan dari proses sistem pengawasan mutu serta perjanjian sistem pengawasan mutu antara Pihak Kedua dengan PT PLN (Persero) Pusat Sertifikasi atau pihak yang ditunjuk oleh Pihak Pertama. Apabila diperlukan, Pihak Pertama dan/atau Wakil Pihak Pertama dan Pihak Kedua dapat menyaksikan pengujian tersebut. (3) Mengacu pada pelaksanaan uji serah terima Barang sebagaimana dimaksud pada ayat (2) Pasal ini, maka akan diterbitkan suatu laporan hasil uji serah terima Barang (Laporan Hasil Uji Serah Terima Barang). (4) Pengujian serah terima Barang mengacu kepada SPLN yang disyaratkan atas Barang dan/atau standar lain yang berlaku. Apabila diperlukan, Pihak Pertama akan melakukan pengujian tambahan termasuk memberikan tambahan mata uji yang dibutuhkan. Seluruh biaya pengujian tambahan Barang menjadi tanggung jawab Pihak Pertama. (5) Apabila Laporan Hasil Uji Serah Terima Barang sebagaimana dimaksud pada ayat (3) Pasal ini gagal, maka Pihak Pertama dapat memberlakukan ketentuan tentang pengawasan mutu yang ditetapkan dalam lingkungan Pihak Pertama termasuk namun tidak terbatas pada Sistem Pengawasan Mutu (SPM) material ketenagalistrikan dan/atau ketentuan lain yang berlaku. (6) Setiap dan seluruh Barang yang diindikasikan gagal sesuai hasil pemeriksaan uji serah terima Barang wajib diganti oleh Pihak Kedua hingga memenuhi spesifikasi sesuai yang diatur dalam Kontrak. (7) Dalam hal terjadi perubahan spesifikasi Barang sehubungan dengan kebutuhan Pihak Pertama atau berdasarkan SPLN yang disyaratkan atas Barang atau standar lain yang berlaku, Pihak Kedua wajib memenuhi perubahan tersebut dan menyerahkan Barang sesuai dengan spesifikasi yang baru yang ditentukan Pihak Pertama. Mekanisme perubahan akan disepakati lebih lanjut oleh Para Pihak. (8) Dalam hal terjadi perubahan komponen Barang karena security of supply dan peningkatan kualitas Barang yang telah lulus uji verifikasi oleh PT PLN (Persero) Pusat Sertifikasi atau pihak yang ditunjuk oleh Pihak Pertama, maka Pihak Kedua dapat mengajukan usulan perubahan tersebut kepada Pihak Pertama dan perubahan hanya dapat dilakukan berdasarkan persetujuan Pihak Pertama. (9) Pihak Kedua hanya akan dan wajib mengirimkan Barang setelah materi uji serah terima Barang dinyatakan lulus dalam Laporan Hasil Uji Serah Terima Barang yang dikeluarkan oleh pihak yang ditunjuk Pihak Pertama. (10) Pihak Kedua dapat mengirimkan Barang yang telah dinyatakan lulus dalam Laporan Hasil Uji Serah Terima Barang yang dilakukan sebelum Kontrak ini ditandatangani, setelah mendapatkan verifikasi tertulis berupa covering letter dari PT PLN (Persero) Pusat Sertifikasi atau pihak yang ditunjuk oleh Pihak Pertama. (11) Apabila terjadi proses investigasi atas kerusakan Barang yang telah terpasang, maka PT PLN (Persero) Pusat Sertifikasi atau pihak yang ditunjuk oleh Pihak Pertama dapat menaikkan jumlah sample Barang yang akan diuji serah terimakan. (12) Pada kondisi khusus dan atas permintaan tertulis dari Pihak Pertama, uji serah terima dan pengiriman Barang akan diatur dengan mekanisme tersendiri. | D47: -
A49: Pasal 11 | B49: PEKERJAAN PENYEDIAAN BARANG | C49: (1) Sejak Tanggal Efektif Kontrak Rinci, Pihak Kedua akan melaksanakan Pekerjaan Penyediaan Barang sesuai dengan jadwal dan jangka waktu sebagaimana dirinci pada Lampiran 3 Kontrak ini. (2) Pihak Kedua berkewajiban atas tanggungannya sendiri untuk mengepak Barang sedemikian rupa sehingga Barang terhindar dan terlindungi dari risiko kerusakan atau kehilangan selama masa transportasi atau pada saat pengiriman dari tempat asal Barang sampai ke Lokasi. (3) Pengepakan, penandaan dan penyertaan dokumen di dalam dan di luar paket Barang harus dilakukan dengan mencantumkan keterangan sebagai berikut: (a) Nama Barang; (b) Nomor Serial; (c) Merek; (d) Tipe/Jenis; (e) Rating; (f) Kontrak No./Tanggal; (g) Kontrak Rinci No./Tanggal; (h) Alamat Tujuan; dan (i) Jumlah Barang. Dapat disesuaikan terhadap kebutuhan masing-masing pengadaan | D49: -
A50: Pasal 12 | B50: PEKERJAAN TRANSPORTASI | C50: (1) Setelah penyelesaian Pekerjaan Penyediaan Barang, Pihak Kedua berkewajiban melakukan Pekerjaan Transportasi berupa pengiriman Barang ke Lokasi. (2) Dalam melakukan Pekerjaan Transportasi, Pihak Kedua berkewajiban memberitahukan terlebih dahulu secara tertulis selambat-lambatnya 7 (tujuh) hari kerja sebelum pengiriman Barang kepada Pengguna Kontrak Rinci untuk setiap pengiriman Barang ke Lokasi. (3) Pihak Kedua wajib membuat surat jalan sebanyak minimal 2 (dua) rangkap yang berisi rincian pengiriman Barang dan dokumen terkait lainnya yang harus diserahkan oleh Pihak Kedua dan akan ditandatangani oleh petugas dari Pengguna Kontrak Rinci pada saat Barang sampai di Lokasi. (4) Pihak Kedua harus mempersiapkan Barang termasuk semua perlengkapannya yang akan dikirimkan ke Lokasi dengan cara transportasi tertentu termasuk kelengkapan peralatan transportasi dan melindunginya dari segala kerusakan atau kerugian serta bertanggung jawab untuk memperbaiki dan/atau mengganti segala kerusakan dan/atau kehilangan Barang termasuk peralatan atas Barang tersebut. (5) Pihak Kedua berkewajiban untuk tunduk dan menaati segala Peraturan perundang-undangan yang berlaku di Negara Kesatuan Republik Indonesia tentang pengiriman dan pendistribusian barang/jasa. (6) Pihak Kedua harus bertanggung jawab untuk mendapatkan perizinan dari pemerintah baik pusat maupun daerah dan/atau instansi lain sehubungan dengan pengurusan transportasi dan pemindahan Barang termasuk perlengkapan atas Barang tersebut. (7) Pihak Kedua harus mentransportasikan semua Barang maupun perlengkapan atas Barang yang tercantum dalam Kontrak ini ke Lokasi dan tetap bertanggung jawab penuh atas pemuatan, pembongkaran, penanganan, pengangkutan, penyimpanan di lapangan dan asuransi yang diperlukan (Transportation Insurance). (8) Semua biaya transportasi atas Pekerjaan Transportasi (termasuk pemuatan dan penyimpanan) adalah sebagaimana tercantum dalam Lampiran 1 Kontrak ini. (9) Pihak Kedua wajib mengasuransikan setiap Barang yang akan diserahkan dan pengiriman Barang sesuai dengan ketentuan peraturan perundang-undangan yang berlaku. Seluruh biaya-biaya yang timbul atas pelaksanaan Pasal ini menjadi beban dan tanggung jawab Pihak Kedua. (10) Apabila Pihak Kedua tidak melakukan pemberitahuan sebagaimana dimaksud pada ayat (2) Pasal ini, sehingga Barang tidak dapat ditempatkan di Lokasi yang bersangkutan, maka segala risiko dan biaya yang timbul menjadi beban dan tanggung jawab Pihak Kedua. (11) Konsekuensi dan risiko terhadap kerusakan dan/atau kehilangan Barang yang terjadi sebelum Barang diserahterimakan oleh Pihak Kedua kepada Pengguna Kontrak Rinci di Lokasi yang dinyatakan dalam setiap BASTB merupakan beban dan tanggung jawab Pihak Kedua. (12) Pihak Pertama memiliki hak setiap saat untuk melakukan transportasi Barang sesuai dengan mekanisme pengiriman Barang atau pengaturan logistik Pihak Pertama. Dalam hal Pihak Pertama melakukan maksudnya tersebut, maka Para Pihak sepakat bahwa Pihak Pertama tidak berkewajiban untuk melakukan pembayaran atas biaya transportasi dan asuransi atas Barang terkait. | D50: -
... A78: Pasal 34 | B78: ADMINISTRASI DAN SURAT MENYURAT | C78: (1) Setiap pemberitahuan yang berkaitan dengan Kontrak ini harus dilaksanakan secara tertulis dalam bentuk surat dan/atau email. Pemberitahuan secara lisan dan/atau telepon harus dikuatkan dengan pemberitahuan secara tertulis dalam bentuk surat dan/atau email dalam waktu 24 (dua puluh empat) jam sejak pemberitahuan lisan atau telepon tersebut disampaikan. (2) Setiap pemberitahuan untuk masing-masing Pihak ditujukan kepada pejabat dengan alamat sebagai berikut : PT PLN (PERSERO) [Nama Unit] Alamat : [Alamat Unit] Facsimile/Telepon : [Nomor Facsimile/Telepon] Untuk perhatian : [Nama Jabatan UP] PT [Masukan Nama Penyedia] Alamat : [Alamat] Facsimile/Telepon : [Nomor Telepon] Untuk perhatian : [Pihak Yang Dituju] Email : [Alamat Email] (3) Apabila terjadi perubahan alamat Para Pihak sebagaimana tercantum pada ayat (2) Pasal ini, maka Para Pihak harus memberitahukan perubahan alamat secara tertulis kepada Pihak lainnya. | D78: Nama Unit
D79: Alamat Unit
D80: Nomor Facsimile/Telepon
D81: Nama Jabatan UP
D82: Nama penyedia Barang/Jasa
D83: Alamat penyedia Barang/Jasa
D84: Nomor Telepon penyedia Barang/Jasa
D85: Pihak yang dituju
D86: Alamat email penyedia Barang/Jasa
...

Sheet Syarat Umum Perjanjian Kontrak 
C1: Pengadaan Barang/Jasa Lainnya | D1: Pengadaan Jasa Konsultansi | E1: Pengadaan Jasa Konstruksi | F1: Pembelian Tenaga Listrik/Uap
C2: 0012.E/DIR/2023 | D2: 0010.E/DIR/2024 | E2: 0013.E/DIR/2024 | F2: 0037.E/DIR/2023
A3: Ketentuan Umum | B3: Definisi | C3: TRUE | D3: TRUE | E3: TRUE | F3: FALSE
B4: Penerapan | C4: TRUE | D4: TRUE | E4: TRUE | F4: FALSE
B5: Asal Barang/Jasa Lainnya | C5: TRUE | D5: FALSE | E5: TRUE | F5: FALSE
B6: Penggunaan Dokumen-Dokumen Perjanjian/Kontrak dan Informasi | C6: TRUE | D6: TRUE | E6: TRUE | F6: FALSE
B7: Hak Paten, Hak Cipta, dan Merek | C7: TRUE | D7: FALSE | E7: TRUE | F7: FALSE
B8: Jaminan | C8: TRUE | D8: FALSE | E8: TRUE | F8: FALSE
B9: Asuransi | C9: TRUE | D9: FALSE | E9: TRUE | F9: FALSE
B10: Pembayaran | C10: TRUE | D10: TRUE | E10: TRUE | F10: FALSE
B11: Harga | C11: TRUE | D11: TRUE | E11: TRUE | F11: FALSE
B12: Adendum/Amandemen Perjanjian/Kontrak | C12: TRUE | D12: TRUE | E12: TRUE | F12: FALSE
B13: Ketentuan Jadwal Pelaksanaan Pekerjaan | C13: TRUE | D13: TRUE | E13: TRUE | F13: FALSE
B14: Pengawasan | C14: TRUE | D14: TRUE | E14: TRUE | F14: FALSE
B15: Keterlambatan Pelaksanaan Pekerjaan | C15: TRUE | D15: TRUE | E15: TRUE | F15: FALSE
... B23: Korespondensi | C23: TRUE | D23: TRUE | E23: TRUE | F23: FALSE
A24: Ketentuan Umum Pembelian Tenaga Listrik/Uap | B24: Kriteria Pembelian Tenaga Listrik/Uap | C24: FALSE | D24: FALSE | E24: FALSE | F24: TRUE
B25: Persyaratan kualifikasi untuk menjadi PPL/Badan Usaha Penyedia Uap | C25: FALSE | D25: FALSE | E25: FALSE | F25: TRUE
B26: Pendayagunaan Produksi Dalam Negeri | C26: FALSE | D26: FALSE | E26: FALSE | F26: TRUE
B27: Metode Pembelian Tenaga Listrik/Uap | C27: FALSE | D27: FALSE | E27: FALSE | F27: TRUE
B28: Pola Kerja Sama | C28: FALSE | D28: FALSE | E28: FALSE | F28: TRUE
A29: Ketentuan Khusus | B29: Kewajiban Penyedia Jasa Konsultansi | C29: FALSE | D29: TRUE | E29: FALSE | F29: FALSE
B30: Personel Konsultan dan Subkonsultan | C30: FALSE | D30: TRUE | E30: FALSE | F30: FALSE
B31: Waktu Kerja dan Lembur | C31: FALSE | D31: TRUE | E31: FALSE | F31: FALSE
B32: Penggantian dan Perpindahan Personel | C32: FALSE | D32: TRUE | E32: FALSE | F32: FALSE
B33: Standar | C33: TRUE | D33: FALSE | E33: TRUE | F33: FALSE
B34: Pengepakan (Packaging) | C34: TRUE | D34: FALSE | E34: TRUE | F34: FALSE
B35: Pengiriman | C35: TRUE | D35: FALSE | E35: TRUE | F35: FALSE
B36: Transportasi | C36: TRUE | D36: FALSE | E36: TRUE | F36: FALSE
B37: Pemeriksaan dan Pengujian | C37: TRUE | D37: FALSE | E37: TRUE | F37: FALSE
B38: Layanan Tambahan | C38: TRUE | D38: FALSE | E38: TRUE | F38: FALSE
B39: Persetujuan Penempatan/Penggantian Personel | C39: FALSE | D39: FALSE | E39: TRUE | F39: FALSE
B40: Ketentuan atas Penemuan Benda/Barang Bernilai Sejarah atau Kekayaan Negara | C40: FALSE | D40: FALSE | E40: TRUE | F40: FALSE
B41: Ketentuan Kompensasi | C41: FALSE | D41: FALSE | E41: TRUE | F41: FALSE
... B43: Pedoman Pengoperasian dan Perawatan | C43: FALSE | D43: FALSE | E43: TRUE | F43: FALSE
A44: Ketentuan PJBL/PJBU *Muatan PJBL/PJBU dapat disesuaikan dengan adanya ketentuan khusus dan/atau disesuaikan dengan maksud dan tujuan pengembangan Pembangkit Energi Baru Terbarukan/Uap yang dimaksud. | B44: Jangka waktu PJBL/PJBU | C44: FALSE | D44: FALSE | E44: FALSE | F44: TRUE
B45: Hak dan kewajiban PPL/Badan Usaha Penyedia Uap selaku penjual dan PLN selaku pembeli | C45: FALSE | D45: FALSE | E45: FALSE | F45: TRUE
B46: Jaminan pelaksanaan proyek | C46: FALSE | D46: FALSE | E46: FALSE | F46: TRUE
B47: Project Development Cost Account (PDCA) | C47: FALSE | D47: FALSE | E47: FALSE | F47: TRUE
B48: Komisioning dan Commercial Operation Date (COD) | C48: FALSE | D48: FALSE | E48: FALSE | F48: TRUE
...

Sheet Pemetaan Jenis Kontrak
B1: Kontrak Biaya Plus Imbalan | C1: Kontrak Gabungan | D1: Kontrak Harga Satuan | E1: Kontrak Kesepakatan Harga Satuan | F1: Kontrak Lumsum | G1: Kontrak Payung | H1: Kontrak Terima Jadi | I1: Kontrak Waktu Penugasan
A3: Identifier Perjanjian | B3: TRUE | C3: TRUE | D3: TRUE | E3: TRUE | F3: TRUE | G3: TRUE | H3: TRUE | I3: TRUE
A4: Dasar Pekerjaan | B4: TRUE | C4: TRUE | D4: TRUE | E4: TRUE | F4: TRUE | G4: TRUE | H4: TRUE | I4: TRUE
A5: Definisi | B5: TRUE | C5: TRUE | D5: TRUE | E5: TRUE | F5: TRUE | G5: TRUE | H5: TRUE | I5: TRUE
A6: Ruang Lingkup Pekerjaan/Perjanjian | B6: TRUE | C6: TRUE | D6: TRUE | E6: TRUE | F6: TRUE | G6: TRUE | H6: TRUE | I6: TRUE
A7: Harga Satuan | B7: FALSE | C7: FALSE | D7: FALSE | E7: TRUE | F7: FALSE | G7: FALSE | H7: FALSE | I7: FALSE
A8: Nilai Perjanjian | B8: TRUE | C8: TRUE | D8: TRUE | E8: FALSE | F8: TRUE | G8: TRUE | H8: TRUE | I8: TRUE
A9: Struktur Organisasi Pelaksanaan | B9: FALSE | C9: TRUE | D9: FALSE | E9: TRUE | F9: TRUE | G9: TRUE | H9: TRUE | I9: FALSE
A10: Jangka Waktu | B10: TRUE | C10: TRUE | D10: TRUE | E10: TRUE | F10: TRUE | G10: TRUE | H10: TRUE | I10: TRUE
A11: Hak, Kewajiban, dan Larangan | B11: TRUE | C11: TRUE | D11: TRUE | E11: FALSE | F11: TRUE | G11: TRUE | H11: TRUE | I11: TRUE
A12: Pola Pengawasan | B12: FALSE | C12: TRUE | D12: TRUE | E12: TRUE | F12: TRUE | G12: FALSE | H12: TRUE | I12: FALSE
A13: SLA & Kriteria Penilaian Pekerjaan | B13: FALSE | C13: TRUE | D13: TRUE | E13: TRUE | F13: TRUE | G13: TRUE | H13: TRUE | I13: TRUE
A14: Manajemen Mutu dan Sistem Verifikasi Kepatuhan | B14: FALSE | C14: TRUE | D14: TRUE | E14: TRUE | F14: TRUE | G14: FALSE | H14: TRUE | I14: FALSE
... A40: Korespondensi | B40: TRUE | C40: TRUE | D40: TRUE | E40: TRUE | F40: TRUE | G40: TRUE | H40: TRUE | I40: TRUE

Sheet Pemetaan Kontrak (backup)
B1: Kontrak Lumsum | F1: Kontrak Harga Satuan | I1: Kontrak Gabungan | L1: Kontrak Terima Jadi | O1: Kontrak Kesepakatan Harga Satuan | R1: Kontrak Payung | S1: Kontrak Waktu Penugasan | T1: Kontrak Biaya Plus Imbalan
B2: Barang | C2: Jasa Lainnya | D2: Jasa Konsultansi | E2: Pekerjaan Konstruksi | F2: Barang | G2: Jasa Lainnya | H2: Pekerjaan Konstruksi | I2: Barang | J2: Jasa Lainnya | K2: Pekerjaan Konstruksi | L2: Barang | M2: Jasa Lainnya | N2: Pekerjaan Konstruksi | O2: Barang | P2: Jasa Lainnya | Q2: Pekerjaan Konstruksi | R2: Jasa Konsultansi | S2: Jasa Konsultansi | T2: Barang | U2: Jasa Lainnya | V2: Pekerjaan Konstruksi
A3: Identifier Perjanjian | B3: TRUE | C3: TRUE | D3: TRUE | E3: TRUE | F3: TRUE | G3: FALSE | H3: FALSE | I3: TRUE | J3: FALSE | K3: FALSE | L3: TRUE | M3: FALSE | N3: FALSE | O3: TRUE | P3: FALSE | Q3: FALSE | R3: TRUE | S3: TRUE | T3: TRUE | U3: FALSE | V3: FALSE
A4: Dasar Pekerjaan | B4: TRUE | C4: TRUE | D4: TRUE | E4: TRUE | F4: TRUE | G4: FALSE | H4: FALSE | I4: TRUE | J4: FALSE | K4: FALSE | L4: TRUE | M4: FALSE | N4: FALSE | O4: TRUE | P4: FALSE | Q4: FALSE | R4: TRUE | S4: TRUE | T4: TRUE | U4: FALSE | V4: FALSE
A5: Definisi | B5: TRUE | C5: TRUE | D5: TRUE | E5: TRUE | F5: TRUE | G5: FALSE | H5: FALSE | I5: TRUE | J5: FALSE | K5: FALSE | L5: TRUE | M5: FALSE | N5: FALSE | O5: TRUE | P5: FALSE | Q5: FALSE | R5: TRUE | S5: TRUE | T5: TRUE | U5: FALSE | V5: FALSE
A6: Ruang Lingkup Pekerjaan/Perjanjian | B6: TRUE | C6: TRUE | D6: TRUE | E6: TRUE | F6: TRUE | G6: FALSE | H6: FALSE | I6: TRUE | J6: FALSE | K6: FALSE | L6: TRUE | M6: FALSE | N6: FALSE | O6: TRUE | P6: FALSE | Q6: FALSE | R6: TRUE | S6: TRUE | T6: TRUE | U6: FALSE | V6: FALSE
A7: Metodologi dan Tahapan Pelaksanaan Pekerjaan | B7: TRUE | C7: TRUE | D7: TRUE | E7: FALSE | F7: FALSE | G7: FALSE | H7: FALSE | I7: FALSE | J7: FALSE | K7: FALSE | L7: FALSE | M7: FALSE | N7: FALSE | O7: FALSE | P7: FALSE | Q7: FALSE | R7: FALSE | S7: FALSE | T7: FALSE | U7: FALSE | V7: FALSE
A8: Nilai Perjanjian | B8: TRUE | C8: TRUE | D8: TRUE | E8: TRUE | F8: TRUE | G8: FALSE | H8: FALSE | I8: TRUE | J8: FALSE | K8: FALSE | L8: TRUE | M8: FALSE | N8: FALSE | O8: FALSE | P8: FALSE | Q8: FALSE | R8: TRUE | S8: TRUE | T8: TRUE | U8: FALSE | V8: FALSE
A9: Harga Satuan | B9: FALSE | C9: FALSE | D9: FALSE | E9: FALSE | F9: FALSE | G9: FALSE | H9: FALSE | I9: FALSE | J9: FALSE | K9: FALSE | L9: FALSE | M9: FALSE | N9: FALSE | O9: TRUE | P9: FALSE | Q9: FALSE | R9: FALSE | S9: FALSE | T9: FALSE | U9: FALSE | V9: FALSE
A10: Non Harga Satuan | B10: TRUE | C10: TRUE | D10: TRUE | E10: TRUE | F10: FALSE | G10: FALSE | H10: FALSE | I10: FALSE | J10: FALSE | K10: FALSE | L10: FALSE | M10: FALSE | N10: FALSE | O10: FALSE | P10: FALSE | Q10: FALSE | R10: FALSE | S10: FALSE | T10: FALSE | U10: FALSE | V10: FALSE
A11: Struktur Organisasi Pelaksanaan | B11: TRUE | C11: TRUE | D11: TRUE | E11: TRUE | F11: FALSE | G11: FALSE | H11: FALSE | I11: TRUE | J11: FALSE | K11: FALSE | L11: TRUE | M11: FALSE | N11: FALSE | O11: TRUE | P11: FALSE | Q11: FALSE | R11: TRUE | S11: FALSE | T11: FALSE | U11: FALSE | V11: FALSE
A12: Jangka Waktu | B12: TRUE | C12: TRUE | D12: TRUE | E12: TRUE | F12: TRUE | G12: FALSE | H12: FALSE | I12: TRUE | J12: FALSE | K12: FALSE | L12: TRUE | M12: FALSE | N12: FALSE | O12: TRUE | P12: FALSE | Q12: FALSE | R12: TRUE | S12: TRUE | T12: TRUE | U12: FALSE | V12: FALSE
A13: Hak, Kewajiban, dan Larangan | B13: TRUE | C13: TRUE | D13: TRUE | E13: TRUE | F13: TRUE | G13: FALSE | H13: FALSE | I13: TRUE | J13: FALSE | K13: FALSE | L13: TRUE | M13: FALSE | N13: FALSE | O13: FALSE | P13: FALSE | Q13: FALSE | R13: TRUE | S13: TRUE | T13: TRUE | U13: FALSE | V13: FALSE
A14: Pola Pengawasan | B14: FALSE | C14: FALSE | D14: FALSE | E14: TRUE | F14: TRUE | G14: FALSE | H14: FALSE | I14: TRUE | J14: FALSE | K14: FALSE | L14: TRUE | M14: FALSE | N14: FALSE | O14: TRUE | P14: FALSE | Q14: FALSE | R14: FALSE | S14: FALSE | T14: FALSE | U14: FALSE | V14: FALSE
... A54: Penutup | B54: TRUE | C54: TRUE | D54: TRUE | E54: TRUE | F54: FALSE | G54: FALSE | H54: FALSE | I54: FALSE | J54: FALSE | K54: FALSE | L54: FALSE | M54: FALSE | N54: FALSE | O54: FALSE | P54: FALSE | Q54: FALSE | R54: FALSE | S54: FALSE | T54: FALSE | U54: FALSE | V54: FALSE

Sheet Master Klausul (backup)
B1: Klausul | C1: Data
A2: Header | B2: Perjanjian/Kontrak [Nomor Perjanjian/Kontrak] tentang [Nama Pekerjaan] Antara PT PLN (Persero) dengan [Nama Penyedia Barang/Jasa] | C2: Nomor Perjanjian
C3: Nama Pekerjaan
C4: Nama Penyedia Barang/Jasa
A5: ='Pemetaan Kontrak '!B9 -> Identifier Perjanjian | B5: Perjanjian [Nama Pekerjaan] berikut semua lampirannya dibuat dan disepakati di [Tempat Perjanjian/Kontrak] pada hari [Hari Penandatanganan] tanggal [Tanggal Penandatanganan] oleh dan antara: I. PT PLN (Persero) : Suatu Perseroan Terbatas yang didirikan berdasarkan hukum Republik Indonesia berdasarkan Akta Nomor 169 tanggal 30 Juli 1994, dibuat oleh dan dihadapan Sutjipto, S.H. Notaris di Jakarta, yang telah diubah beberapa kali, terakhir dilakukan perubahan sebagaimana Akta No. 12 tanggal 25 Maret 2021 dibuat oleh dan dihadapan Lenny Janis Ishak, SH. Notaris di Jakarta, yang dalam hal ini di wakili oleh [Nama pejabat yang menandatangani] selaku [Jabatan Penandatangan] PT PLN (Persero) [Nama Unit] berdasarkan Keputusan Direksi PT PLN (Persero) Nomor: [Nomor KepDir] tentang [Judul KepDir], sehingga dalam hal ini berhak dan berwenang bertindak untuk dan atas nama PT PLN (Persero), berkedudukan di [Nama Unit], untuk selanjutnya disebut sebagai PIHAK PERTAMA II. [Nama Penyedia Barang/Jasa] : Suatu [Bentuk Badan Usaha] yang didirikan berdasarkan Hukum Republik Indonesia berdasarkan Akta No. [Nomor Akta Pendirian Perusahaan] tanggal [Tanggal Akta Pendirian] dibuat oleh dan dihadapan [Nama Notaris Pembuat Akta], Notaris di [Kota Notaris], yang telah diubah beberapa kali, terakhir dilakukan perubahan sebagaimana Akta Nomor [Nomor Akta Perubahan Terakhir] tanggal [Tanggal Perubahan Terakhir] dibuat oleh dan dihadapan [Nama Notaris Pembuat Akta], Notaris di [Kota Notaris] yang dalam hal ini diwakili oleh [Nama perwakilan perusahaan] selaku [Jabatan perwakilan] sehingga dalam hal ini berhak dan bewenang bertindak untuk dan atas nama [Nama Penyedia Barang/Jasa], berkedudukan di [Alamat/Kota Domisili Penyedia Barang/Jasa], untuk selanjutnya disebut sebagai PIHAK KEDUA Untuk selanjutnya PIHAK PERTAMA dan PIHAK KEDUA secara sendiri-sendiri disebut PIHAK dan secara Bersama-sama disebut PARA PIHAK. | C5: Nama Pekerjaan
C6: Tempat Perjanjian
C7: Hari penandatanganan
C8: Tanggal Penandatanganan
C9: Nama pejabat yang menandatangani
C10: Nama Unit
C11: Nomor KepDir
C12: Judul KepDir
C13: Nama Penyedia Barang/Jasa
C14: Bentuk Badan Usaha
C15: Nomor Akta Pendirian Perusahaan
C16: Tanggal Akta Pendirian
C17: Nama Notaris Pembuat Akta
... C22: Alamat/kota domisili Penyedia Barang/Jasa
